Workbook

Sheet Bar chart → City vs Profit
H2: Dashboard Summary | I2: KPIs
H3: Total sales | I3: =SUM('Online Store Data'!$G$2:$G$13) -> 147800
H4: Avg discount | I4: =AVERAGE('Online Store Data'!$I$2:$I$13) -> 0.1025
H5: Total profit | I5: =SUM(Table1[Profit]) -> 134020
A9: Row Labels | B9: Sum of Profit
A10: Bangalore | B10: 63290
A11: Delhi | B11: 39400
A12: Mumbai | B12: 31330
A13: Grand Total | B13: 134020
A31: Row Labels | B31: Sum of Sales
A32: Electronics | B32: 110000
A33: Furniture | B33: 29000
A34: Clothing | B34: 8800
A35: Grand Total | B35: 147800

Sheet Data Analyst Thinking Question
A3: Row Labels | B3: Sum of Sales | C3: Sum of Profit
A4: Electronics | B4: 110000 | C4: 102190
A5: Furniture | B5: 29000 | C5: 23760
A6: Clothing | B6: 8800 | C6: 8070
A7: Grand Total | B7: 147800 | C7: 134020
A10: Ques -> | B10: Which category performs best?
A11: Answer -> | B11: Electronics because sales and Profit both high
A14: Row Labels | B14: Average of Discount | C14: Sum of Sales | D14: Sum of Profit
A15: Table | B15: 0.2 | C15: 7000 | D15: 5600
A16: Sofa | B16: 0.18 | C16: 18000 | D16: 14760
A17: Chair | B17: 0.15 | C17: 4000 | D17: 3400
A18: Headphones | B18: 0.12 | C18: 3000 | D18: 2640
A19: T-shirt | B19: 0.1 | C19: 800 | D19: 720
A20: Jacket | B20: 0.1 | C20: 3500 | D20: 3150
A21: Dress | B21: 0.08 | C21: 2500 | D21: 2300
A22: Laptop | B22: 0.08 | C22: 60000 | D22: 55200
A23: Tablet | B23: 0.07 | C23: 15000 | D23: 13950
A24: Smartwatch | B24: 0.05 | C24: 12000 | D24: 11400
A25: Jeans | B25: 0.05 | C25: 2000 | D25: 1900
A26: Mobile | B26: 0.05 | C26: 20000 | D26: 19000
A27: Grand Total | B27: 0.1025 | C27: 147800 | D27: 134020
A29: Ques -> | B29: Does high discount reduce profit?
A30: Asnwer -> | B30: yes
A33: Row Labels | B33: Sum of Quantity
A34: Headphones | B34: 3
A35: T-shirt | B35: 2
A36: Dress | B36: 2
A37: Chair | B37: 2
A38: Jeans | B38: 1
A39: Table | B39: 1
A40: Sofa | B40: 1
A41: Jacket | B41: 1
A42: Tablet | B42: 1
A43: Mobile | B43: 1
A44: Smartwatch | B44: 1
A45: Laptop | B45: 1
A46: Grand Total | B46: 17
A48: Ques -> | B48: Which product sells most quantity?
A49: Answer -> | B49: Headphones
A52: Row Labels | B52: Sum of Sales
...

Sheet Online Store Data
A1: Order ID | B1: Date | C1: Customer | D1: City | E1: Category | F1: Product | G1: Sales | H1: Quantity | I1: Discount | J1: Profit | K1: Profit_Type
A2: 3001 | B2: 01-03-2026 | C2: Aakash | D2: Delhi | E2: Electronics | F2: Mobile | G2: 20000 | H2: 1 | I2: 0.05 | J2: =G2-(G2*I2) -> 19000 | K2: =IF(J2>10000,"High",(IF(J2>5000,"Medium","Low"))) -> High
A3: 3002 | B3: 02-03-2026 | C3: Neha | D3: Mumbai | E3: Clothing | F3: T-shirt | G3: 800 | H3: 2 | I3: 0.1 | J3: =G3-(G3*I3) -> 720 | K3: =IF(J3>10000,"High",(IF(J3>5000,"Medium","Low"))) -> Low
A4: 3003 | B4: 03-03-2026 | C4: Rahul | D4: Bangalore | E4: Electronics | F4: Laptop | G4: 60000 | H4: 1 | I4: 0.08 | J4: =G4-(G4*I4) -> 55200 | K4: =IF(J4>10000,"High",(IF(J4>5000,"Medium","Low"))) -> High
A5: 3004 | B5: 04-03-2026 | C5: Priya | D5: Delhi | E5: Furniture | F5: Chair | G5: 4000 | H5: 2 | I5: 0.15 | J5: =G5-(G5*I5) -> 3400 | K5: =IF(J5>10000,"High",(IF(J5>5000,"Medium","Low"))) -> Low
A6: 3005 | B6: 05-03-2026 | C6: Karan | D6: Mumbai | E6: Clothing | F6: Jeans | G6: 2000 | H6: 1 | I6: 0.05 | J6: =G6-(G6*I6) -> 1900 | K6: =IF(J6>10000,"High",(IF(J6>5000,"Medium","Low"))) -> Low
A7: 3006 | B7: 06-03-2026 | C7: Simran | D7: Bangalore | E7: Electronics | F7: Headphones | G7: 3000 | H7: 3 | I7: 0.12 | J7: =G7-(G7*I7) -> 2640 | K7: =IF(J7>10000,"High",(IF(J7>5000,"Medium","Low"))) -> Low
A8: 3007 | B8: 07-03-2026 | C8: Arjun | D8: Delhi | E8: Furniture | F8: Table | G8: 7000 | H8: 1 | I8: 0.2 | J8: =G8-(G8*I8) -> 5600 | K8: =IF(J8>10000,"High",(IF(J8>5000,"Medium","Low"))) -> Medium
A9: 3008 | B9: 08-03-2026 | C9: Riya | D9: Mumbai | E9: Electronics | F9: Tablet | G9: 15000 | H9: 1 | I9: 0.07 | J9: =G9-(G9*I9) -> 13950 | K9: =IF(J9>10000,"High",(IF(J9>5000,"Medium","Low"))) -> High
A10: 3009 | B10: 09-03-2026 | C10: Vikas | D10: Bangalore | E10: Clothing | F10: Jacket | G10: 3500 | H10: 1 | I10: 0.1 | J10: =G10-(G10*I10) -> 3150 | K10: =IF(J10>10000,"High",(IF(J10>5000,"Medium","Low"))) -> Low
A11: 3010 | B11: 10-03-2026 | C11: Pooja | D11: Delhi | E11: Electronics | F11: Smartwatch | G11: 12000 | H11: 1 | I11: 0.05 | J11: =G11-(G11*I11) -> 11400 | K11: =IF(J11>10000,"High",(IF(J11>5000,"Medium","Low"))) -> High
A12: 3011 | B12: 11-03-2026 | C12: Manish | D12: Mumbai | E12: Furniture | F12: Sofa | G12: 18000 | H12: 1 | I12: 0.18 | J12: =G12-(G12*I12) -> 14760 | K12: =IF(J12>10000,"High",(IF(J12>5000,"Medium","Low"))) -> High
A13: 3012 | B13: 12-03-2026 | C13: Sneha | D13: Bangalore | E13: Clothing | F13: Dress | G13: 2500 | H13: 2 | I13: 0.08 | J13: =G13-(G13*I13) -> 2300 | K13: =IF(J13>10000,"High",(IF(J13>5000,"Medium","Low"))) -> Low

Sheet Analysis aggregate function
A1: KPIs | B1: Analysis
A2: Total sales | B2: =SUM('Online Store Data'!$G$2:$G$13) -> 147800
A3: Avg discount | B3: =AVERAGE('Online Store Data'!$I$2:$I$13) -> 0.1025
A4: Total profit | B4: =SUM(Table1[Profit]) -> 134020
A5: Max sales value | B5: =MAX('Online Store Data'!$G$2:$G$13) -> 60000
A6: Min sales value | B6: =MIN('Online Store Data'!$G$2:$G$13) -> 800
A7: Total Quantity sold | B7: =SUM('Online Store Data'!$H$2:$H$13) -> 17
